<robot name="imu" xmlns:xacro="http://www.ros.org/wiki/xacro">
    <xacro:macro name="imu" params="name parent *origin">

        <joint name='${name}_joint' type='revolute'>
            <parent link="${parent}" />
            <child link="${name}" />
            <xacro:insert_block name="origin"/>
        </joint>

        <link name="${name}">
            <inertial>
                <mass>0.015</mass>
                <inertia ixx="1e-05" ixy="0" ixz="0" iyy="1e-05" iyz="0" izz="1e-05" />
            </inertial>
        </link>
    </xacro:macro>
</robot>
